Workbook

Sheet README
A1: AI Cost Allocation Schema & Mapping Workbook
A3: Purpose | B3: Operational data dictionary + provider mapping for an AI cost ingestion-and-normalization layer. Use it as the lookup table that any billing source (cloud CUR/FOCUS export, SaaS invoice, API usage dump, labor allocation) normalizes against.
A4: How to use | B4: 1) Normalize every cost line to the fields in 'Schema_Fields'. 2) Validate enum fields against 'Enumerations'. 3) Map each provider's native SKU to ServiceName -> CostDomain -> PricingUnit using 'Provider_Mapping'. 4) Drive optimization from 'Cost_Driver_Lever_Map'.
A5: Four axes | B5: The schema separates axes a flat list collapses: DeploymentModel (where it runs), ModelChannel (how the model is accessed), CostDomain (what you pay for), and WorkloadLifecycle (which stage). Slice spend on any of them.
A6: FOCUS | B6: Identity/pricing/commitment fields align to FOCUS columns. AI-native extensions (token types, cache asymmetry, ModelChannel/Tier, amplification, idle-GPU/endpoint waste) are flagged in Schema_Fields as not-yet-in-FOCUS.
A7: Pricing note | B7: Dollar figures in 'Cost watch-out' notes are directional context as of mid-2026 and move frequently. Treat the STRUCTURE (pricing unit, commitment type, waste pattern) as the durable part; verify rates at the provider before budgeting.
A8: Scope of mapping | B8: Three hyperscalers (AWS, Azure, GCP), the most common direct lab APIs (OpenAI, Anthropic, Google Gemini API), two neoclouds (CoreWeave, Lambda), and two vector-DB SaaS (Pinecone, Weaviate).
A10: Tabs
A11: Schema_Fields | B11: The normalized cost record: every field, its group, type, allowed-value reference, and FOCUS alignment.
A12: Enumerations | B12: Allowed values for each controlled (enum) field - use for dropdown / ingestion validation.
A13: Provider_Mapping | B13: Native services/SKUs per provider mapped to CostDomain, PricingUnit, channel, commitment eligibility, lifecycle, and the cost watch-out.
A14: Cost_Driver_Lever_Map | B14: Each major cost driver paired with the lever(s) that reduce it, the mechanism, typical impact, and the trade-off.

Sheet Reporting
A1: Reporting - AI Spend Summary
A2: Live formulas over Normalized_Data (rows 2-1000). Paste more normalized rows and recalc to refresh.
A4: Total AI spend (period) | B4: =SUM(Normalized_Data!$V$2:$V$1000) -> 63683.14
A6: Spend by CostDomain
A7: CostDomain | B7: Spend | C7: % of total
A8: inference | B8: =SUMIF(Normalized_Data!$D$2:$D$1000,A8,Normalized_Data!$V$2:$V$1000) -> 15805.12 | C8: =IF($B$4=0,0,B8/$B$4) -> 0.24818374
A9: training | B9: =SUMIF(Normalized_Data!$D$2:$D$1000,A9,Normalized_Data!$V$2:$V$1000) -> 1356.77 | C9: =IF($B$4=0,0,B9/$B$4) -> 0.021305011
A10: compute-infra | B10: =SUMIF(Normalized_Data!$D$2:$D$1000,A10,Normalized_Data!$V$2:$V$1000) -> 43497.3 | C10: =IF($B$4=0,0,B10/$B$4) -> 0.68302694
A11: storage | B11: =SUMIF(Normalized_Data!$D$2:$D$1000,A11,Normalized_Data!$V$2:$V$1000) -> 358.75 | C11: =IF($B$4=0,0,B11/$B$4) -> 0.0056333592
A12: networking | B12: =SUMIF(Normalized_Data!$D$2:$D$1000,A12,Normalized_Data!$V$2:$V$1000) -> 82.8 | C12: =IF($B$4=0,0,B12/$B$4) -> 0.0013001871
A13: retrieval-RAG | B13: =SUMIF(Normalized_Data!$D$2:$D$1000,A13,Normalized_Data!$V$2:$V$1000) -> 782.6 | C13: =IF($B$4=0,0,B13/$B$4) -> 0.012288967
A14: orchestration-agents | B14: =SUMIF(Normalized_Data!$D$2:$D$1000,A14,Normalized_Data!$V$2:$V$1000) -> 24.8 | C14: =IF($B$4=0,0,B14/$B$4) -> 0.00038942803
A15: data-prep | B15: =SUMIF(Normalized_Data!$D$2:$D$1000,A15,Normalized_Data!$V$2:$V$1000) -> 0 | C15: =IF($B$4=0,0,B15/$B$4) -> 0
A16: evaluation | B16: =SUMIF(Normalized_Data!$D$2:$D$1000,A16,Normalized_Data!$V$2:$V$1000) -> 0 | C16: =IF($B$4=0,0,B16/$B$4) -> 0
A17: guardrails-safety | B17: =SUMIF(Normalized_Data!$D$2:$D$1000,A17,Normalized_Data!$V$2:$V$1000) -> 0 | C17: =IF($B$4=0,0,B17/$B$4) -> 0
A18: observability | B18: =SUMIF(Normalized_Data!$D$2:$D$1000,A18,Normalized_Data!$V$2:$V$1000) -> 0 | C18: =IF($B$4=0,0,B18/$B$4) -> 0
A19: licensing-subscription | B19: =SUMIF(Normalized_Data!$D$2:$D$1000,A19,Normalized_Data!$V$2:$V$1000) -> 1775 | C19: =IF($B$4=0,0,B19/$B$4) -> 0.027872369
... A24: indirect-overhead | B24: =SUMIF(Normalized_Data!$D$2:$D$1000,A24,Normalized_Data!$V$2:$V$1000) -> 0 | C24: =IF($B$4=0,0,B24/$B$4) -> 0
A26: Spend by DeploymentModel
A27: DeploymentModel | B27: Spend | C27: % of total
A28: managed-API | B28: =SUMIF(Normalized_Data!$E$2:$E$1000,A28,Normalized_Data!$V$2:$V$1000) -> 250.82 | C28: =IF($B$4=0,0,B28/$B$4) -> 0.0039385621
A29: hyperscaler-platform | B29: =SUMIF(Normalized_Data!$E$2:$E$1000,A29,Normalized_Data!$V$2:$V$1000) -> 16133.8 | C29: =IF($B$4=0,0,B29/$B$4) -> 0.25334492
A30: self-hosted-cloud-GPU | B30: =SUMIF(Normalized_Data!$E$2:$E$1000,A30,Normalized_Data!$V$2:$V$1000) -> 3526.07 | C30: =IF($B$4=0,0,B30/$B$4) -> 0.055368972
A31: neocloud | B31: =SUMIF(Normalized_Data!$E$2:$E$1000,A31,Normalized_Data!$V$2:$V$1000) -> 41538 | C31: =IF($B$4=0,0,B31/$B$4) -> 0.65226055
A32: private-cloud-on-prem | B32: =SUMIF(Normalized_Data!$E$2:$E$1000,A32,Normalized_Data!$V$2:$V$1000) -> 0 | C32: =IF($B$4=0,0,B32/$B$4) -> 0
A33: colocation | B33: =SUMIF(Normalized_Data!$E$2:$E$1000,A33,Normalized_Data!$V$2:$V$1000) -> 0 | C33: =IF($B$4=0,0,B33/$B$4) -> 0
A34: edge | B34: =SUMIF(Normalized_Data!$E$2:$E$1000,A34,Normalized_Data!$V$2:$V$1000) -> 0 | C34: =IF($B$4=0,0,B34/$B$4) -> 0
A35: SaaS-embedded | B35: =SUMIF(Normalized_Data!$E$2:$E$1000,A35,Normalized_Data!$V$2:$V$1000) -> 2234.45 | C35: =IF($B$4=0,0,B35/$B$4) -> 0.035086995
A37: Spend by WorkloadLifecycle
A38: WorkloadLifecycle | B38: Spend | C38: % of total
A39: experimentation | B39: =SUMIF(Normalized_Data!$J$2:$J$1000,A39,Normalized_Data!$V$2:$V$1000) -> 0 | C39: =IF($B$4=0,0,B39/$B$4) -> 0
A40: training | B40: =SUMIF(Normalized_Data!$J$2:$J$1000,A40,Normalized_Data!$V$2:$V$1000) -> 25548.77 | C40: =IF($B$4=0,0,B40/$B$4) -> 0.40118578
A41: fine-tuning | B41: =SUMIF(Normalized_Data!$J$2:$J$1000,A41,Normalized_Data!$V$2:$V$1000) -> 0 | C41: =IF($B$4=0,0,B41/$B$4) -> 0
A42: batch-inference | B42: =SUMIF(Normalized_Data!$J$2:$J$1000,A42,Normalized_Data!$V$2:$V$1000) -> 46.5 | C42: =IF($B$4=0,0,B42/$B$4) -> 0.00073017756
A43: real-time-inference | B43: =SUMIF(Normalized_Data!$J$2:$J$1000,A43,Normalized_Data!$V$2:$V$1000) -> 37447.08 | C43: =IF($B$4=0,0,B43/$B$4) -> 0.58802188
A44: evaluation | B44: =SUMIF(Normalized_Data!$J$2:$J$1000,A44,Normalized_Data!$V$2:$V$1000) -> 0 | C44: =IF($B$4=0,0,B44/$B$4) -> 0
A45: data-prep | B45: =SUMIF(Normalized_Data!$J$2:$J$1000,A45,Normalized_Data!$V$2:$V$1000) -> 161.74 | C45: =IF($B$4=0,0,B45/$B$4) -> 0.0025397617
A46: serving-idle | B46: =SUMIF(Normalized_Data!$J$2:$J$1000,A46,Normalized_Data!$V$2:$V$1000) -> 479.05 | C46: =IF($B$4=0,0,B46/$B$4) -> 0.0075223992
A48: Spend by Provider
A49: Provider | B49: Spend | C49: % of total
...

Sheet Schema_Fields
A1: Schema Fields - Normalized AI Cost Record
A3: Field | B3: Group | C3: Type | D3: Required | E3: Allowed Values / Reference | F3: FOCUS Alignment | G3: Notes
A4: ProviderName | B4: Identity | C4: enum | D4: Y | E4: Enumerations | F4: BillingAccount context / ProviderName | G4: Who you pay: AWS, Azure, GCP, OpenAI, Anthropic, CoreWeave, Pinecone, internal, etc.
A5: BillingSourceId | B5: Identity | C5: string | D5: Y | E5: - | F5: SubAccountId / BillingAccountId | G5: Account / subscription / project / invoice identifier.
A6: ServiceName | B6: Identity | C6: string | D6: Y | E6: Provider_Mapping | F6: ServiceName | G6: Provider's native service (e.g. Amazon Bedrock, Vertex Agent Engine).
A7: ChargeDescription | B7: Identity | C7: string | D7: N | E7: - | F7: ChargeDescription / SkuId | G7: Native line-item / SKU string.
A8: ChargeCategory | B8: Identity | C8: enum | D8: Y | E8: Enumerations | F8: ChargeCategory | G8: Usage, Purchase, Tax, Credit, Adjustment, Refund.
A9: DeploymentModel | B9: Sourcing | C9: enum | D9: Y | E9: Enumerations | F9: extension | G9: WHERE it runs. Covers cloud, SaaS, neocloud, colo, API, self-hosted GPU, edge.
A10: ModelChannel | B10: Sourcing | C10: enum | D10: N | E10: Enumerations | F10: extension (AI-native) | G10: HOW the model is accessed. Same model can bill via several channels.
A11: ModelProvider | B11: Sourcing | C11: enum | D11: N | E11: Enumerations | F11: extension | G11: Who built the model (Anthropic, OpenAI, Google, Meta, Mistral...).
A12: ModelTier | B12: Sourcing | C12: enum | D12: N | E12: Enumerations | F12: extension (AI-native) | G12: Capability/cost class: frontier, mid, small, embedding, image, etc.
A13: ModelName | B13: Sourcing | C13: string | D13: N | E13: - | F13: extension | G13: Exact model SKU - for cross-channel reconciliation.
A14: ModelVersion | B14: Sourcing | C14: string | D14: N | E14: - | F14: extension | G14: Version - drives re-eval cost tracking on model updates.
... A34: AmplificationFactor | B34: Governance | C34: number | D34: N | E34: - | F34: extension (AI-native) | G34: Model calls per user request - agentic fan-out tracking.

Sheet Enumerations
A1: Enumerations - Allowed Values for Controlled Fields
A3: Field | B3: Allowed Value | C3: Definition
A4: ChargeCategory | B4: Usage | C4: Metered consumption of a service.
A5: ChargeCategory | B5: Purchase | C5: Upfront / commitment purchase (reservation, prepaid credit).
A6: ChargeCategory | B6: Tax | C6: Tax line.
A7: ChargeCategory | B7: Credit | C7: Discount, promo, or refundable credit.
A8: ChargeCategory | B8: Adjustment | C8: Billing adjustment / true-up.
A9: ChargeCategory | B9: Refund | C9: Refunded amount.
A10: DeploymentModel | B10: managed-API | C10: Pure token/unit consumption of a hosted model API; no infra ownership.
A11: DeploymentModel | B11: hyperscaler-platform | C11: AI service consumed on AWS/Azure/GCP (Bedrock/Foundry/Vertex).
A12: DeploymentModel | B12: self-hosted-cloud-GPU | C12: Your stack on rented cloud GPUs (EC2/AKS/GKE).
A13: DeploymentModel | B13: neocloud | C13: Specialized GPU cloud (CoreWeave, Lambda, etc.).
A14: DeploymentModel | B14: private-cloud-on-prem | C14: Owned infrastructure; adds facilities/depreciation.
... A113: WasteFlag | B113: none | C113: No waste flag.

Sheet Provider_Mapping
A1: Provider Mapping - Native Services to Cost Categories
A3: Provider | B3: Provider Type | C3: Service / SKU | D3: CostDomain | E3: PricingUnit | F3: PricingModel | G3: DeploymentModel | H3: ModelChannel | I3: Commit. Eligible | J3: WorkloadLifecycle | K3: Cost watch-out
A4: AWS | B4: Hyperscaler | C4: Amazon Bedrock | D4: inference | E4: per input/output token | F4: on-demand / batch / priority / flex | G4: hyperscaler-platform | H4: marketplace | I4: via Provisioned Throughput | J4: real-time-inference | K4: batch -50%, priority +75%, flex -50%; Claude bills as CCUs on AWS Marketplace
A5: AWS | B5: Hyperscaler | C5: Bedrock Provisioned Throughput | D5: inference | E5: per model-unit-hour | F5: provisioned-throughput | G5: hyperscaler-platform | H5: marketplace | I5: yes | J5: real-time-inference | K5: reserved capacity bills whether used; term commitment
A6: AWS | B6: Hyperscaler | C6: Bedrock Knowledge Bases / Managed KB | D6: retrieval-RAG | E6: per store + retrieve (+ OpenSearch OCU-hr) | F6: on-demand | G6: hyperscaler-platform | H6: n/a | I6: no | J6: real-time-inference | K6: spins up OpenSearch Serverless: ~$350/mo min floor at zero traffic
A7: AWS | B7: Hyperscaler | C7: Bedrock Agents / AgentCore | D7: orchestration-agents | E7: per tool-invocation + CloudWatch | F7: on-demand | G7: hyperscaler-platform | H7: n/a | I7: no | J7: real-time-inference | K7: call amplification: one query -> many billed calls
A8: AWS | B8: Hyperscaler | C8: Bedrock Guardrails | D8: guardrails-safety | E8: per policy unit | F8: on-demand | G8: hyperscaler-platform | H8: n/a | I8: no | J8: real-time-inference | K8: per-request; scales with traffic
A9: AWS | B9: Hyperscaler | C9: Bedrock custom model (fine-tune) | D9: training | E9: per training token + model storage/mo | F9: on-demand | G9: hyperscaler-platform | H9: fine-tuned-hosted | I9: via PT | J9: fine-tuning | K9: serving a custom text model generally needs Provisioned Throughput
A10: AWS | B10: Hyperscaler | C10: Bedrock model evaluation | D10: evaluation | E10: inference + $0.21/human task | F10: on-demand | G10: hyperscaler-platform | H10: n/a | I10: no | J10: evaluation | K10: human-eval charges land on the SageMaker line item
A11: AWS | B11: Hyperscaler | C11: SageMaker AI - training jobs | D11: training | E11: per ml. instance-hour | F11: on-demand / savings-plan | G11: self-hosted-cloud-GPU | H11: n/a | I11: yes | J11: training | K11: ml. instances ~20-40% over raw EC2; p4d.24xlarge ~$37.69/hr
A12: AWS | B12: Hyperscaler | C12: SageMaker AI - inference endpoints | D12: inference | E12: per ml. instance-hour or per-request | F12: on-demand / serverless / SP | G12: hyperscaler-platform | H12: n/a | I12: yes | J12: real-time-inference | K12: idle endpoints = ghost charges
A13: AWS | B13: Hyperscaler | C13: SageMaker Studio / notebooks | D13: compute-infra | E13: per instance-hour | F13: on-demand | G13: self-hosted-cloud-GPU | H13: n/a | I13: no | J13: experimentation | K13: left-running notebooks accrue
A14: AWS | B14: Hyperscaler | C14: SageMaker Pipelines/Monitor/Clarify/Feature Store | D14: data-prep | E14: per job / instance-hour | F14: on-demand | G14: hyperscaler-platform | H14: n/a | I14: partial | J14: data-prep | K14: MLOps sprawl across many sub-services
... A103: Weaviate | B103: Vector DB SaaS | C103: Dedicated Cloud | D103: retrieval-RAG | E103: fixed infrastructure (contact sales) | F103: provisioned-throughput | G103: SaaS-embedded | H103: n/a | I103: yes | J103: real-time-inference | K103: for compliance + scale; predictable vs AU billing

Sheet Cost_Driver_Lever_Map
A1: Cost Driver -> Lever Map
A3: Cost Driver | B3: CostDomain | C3: Lever | D3: Mechanism | E3: Typical Impact | F3: Trade-off / Risk | G3: Applies To
A4: High output / reasoning token spend | B4: inference | C4: Constrain output & reasoning effort | D4: Cap max_tokens; set reasoning effort low where supported; tighten prompts | E4: 10-40% on output-heavy workloads | F4: May reduce completeness/quality on hard tasks | G4: All token-billed
A5: Repeated context (system prompts, RAG chunks, manuals) | B5: inference | C5: Prompt caching | D5: Cache static prefix; reads at ~10% of input rate | E5: Up to 90% on repeated input | F5: Cache-write surcharge; TTL expiry; exact-match required | G5: direct-API, hyperscaler-platform
A6: Non-urgent / offline jobs | B6: inference | C6: Batch tier | D6: Async 24h processing at -50% in/out | E6: 50% on eligible volume | F6: Latency unacceptable for user-facing work | G6: direct-API, hyperscaler-platform
A7: Over-powered model for simple tasks | B7: inference | C7: Model right-sizing / routing | D7: Route by task complexity to smallest adequate model (or Model Optimizer) | E7: 10-25x on mismatched calls | F7: Routing logic + eval overhead; quality regressions | G7: All model channels
A8: Bursty traffic on reserved capacity | B8: inference / compute-infra | C8: Match commitment to baseline only | D8: Reserve steady baseline; burst on-demand | E8: Eliminates unused-commitment waste | F8: Under-reserving risks throttling | G8: provisioned / PTU / reserved
A9: Idle GPU instances | B9: compute-infra | C9: Idle detection + auto-stop / scale-to-zero | D9: Scheduled shutdown; serverless inference; spot for fault-tolerant jobs | E9: 20-60% of self-hosted spend | F9: Cold-start latency; spot preemption | G9: self-hosted-cloud-GPU, neocloud
A10: Ghost / idle inference endpoints | B10: inference / compute-infra | C10: Endpoint TTL + auto-undeploy | D10: Scan zero-traffic endpoints; undeploy dev after N hours | E10: Removes standing ghost spend | F10: Redeploy latency | G10: hyperscaler-platform
A11: RAG vector-store standing floor | B11: retrieval-RAG | C11: Right-size or consolidate vector store | D11: Share namespaces; consolidate indexes; evaluate self-host at scale | E11: Removes per-index floors; 3-10x at >50M vectors | F11: Namespace isolation vs performance; ops burden if self-hosted | G11: All RAG
A12: Agent call amplification | B12: orchestration-agents | C12: Cap agent steps + cache intermediates | D12: Bound loop depth; semantic cache; intent-gate tool calls | E12: Proportional to fan-out reduction | F12: May truncate legitimate multi-step reasoning | G12: Agent stacks
A13: Data egress | B13: networking | C13: Co-locate compute & data; minimize cross-region | D13: Keep data with GPUs; choose no-egress neocloud; store source-of-truth in object storage | E13: Eliminates egress lines (neoclouds $0) | F13: Provider lock-in considerations | G13: hyperscaler, vector-DB migration
A14: Managed-service markup | B14: compute-infra | C14: Self-manage where ops capacity exists | D14: Run on raw EC2/GKE/neocloud vs managed (SageMaker ml.) | E14: Removes 20-40% markup | F14: Adds ops / on-call burden | G14: hyperscaler-platform
... A23: Embedding re-generation | B23: data-prep | C23: Persist & reuse embeddings | D23: Store embeddings in object storage; re-hydrate vs re-embed | E23: Avoids repeat embedding cost + egress | F23: Storage cost; staleness management | G23: RAG stacks

Sheet Normalized_Data
A1: source_file | B1: ProviderName | C1: ServiceName | D1: CostDomain | E1: DeploymentModel | F1: ModelChannel | G1: ModelProvider | H1: ModelTier | I1: ModelName | J1: WorkloadLifecycle | K1: PricingUnit | L1: PricingModel | M1: CommitmentDiscountType | N1: CommitmentDiscountStatus | O1: CommitmentEligible | P1: ChargeCategory | Q1: Environment | R1: BusinessUnit | S1: GovernanceStatus | T1: WasteFlag | U1: Quantity | V1: BilledCost
A2: focus_aws_export.csv | B2: AWS | C2: Amazon Bedrock | D2: inference | E2: hyperscaler-platform | F2: hyperscaler-marketplace | G2: Anthropic | H2: frontier | I2: claude-opus-4-8 | J2: real-time-inference | K2: tokens | L2: on-demand | M2: none | O2: FALSE | P2: Usage | Q2: prod | R2: customer-support | S2: governed | T2: none | U2: 48200000 | V2: 361.5
A3: focus_aws_export.csv | B3: AWS | C3: Amazon Bedrock | D3: inference | E3: hyperscaler-platform | F3: hyperscaler-marketplace | G3: Anthropic | H3: mid | I3: claude-sonnet-4-6 | J3: real-time-inference | K3: model-unit-Hrs | L3: committed-savings-plan | M3: provisioned-throughput-unit | N3: Used | O3: TRUE | P3: Usage | Q3: prod | R3: search | S3: governed | T3: none | U3: 720 | V3: 15249.6
A4: focus_aws_export.csv | B4: AWS | C4: Amazon SageMaker | D4: training | E4: self-hosted-cloud-GPU | F4: n/a | J4: training | K4: Hrs | L4: committed-savings-plan | M4: savings-plan | N4: Used | O4: TRUE | P4: Usage | Q4: non-prod | R4: ml-platform | S4: governed | T4: none | U4: 36 | V4: 1356.77
A5: focus_aws_export.csv | B5: AWS | C5: Amazon Elastic Compute Cloud | D5: compute-infra | E5: self-hosted-cloud-GPU | F5: n/a | J5: real-time-inference | K5: Hrs | L5: on-demand | M5: none | O5: FALSE | P5: Usage | Q5: non-prod | R5: ml-platform | S5: governed | T5: none | U5: 210 | V5: 2068.5
A6: focus_aws_export.csv | B6: AWS | C6: Amazon SageMaker | D6: compute-infra | E6: self-hosted-cloud-GPU | F6: n/a | J6: serving-idle | K6: Hrs | L6: committed-savings-plan | M6: savings-plan | N6: Unused | O6: TRUE | P6: Usage | Q6: non-prod | R6: ml-platform | S6: governed | T6: unused-commitment | U6: 48 | V6: 100.8
A7: focus_aws_export.csv | B7: AWS | C7: Amazon OpenSearch Service | D7: retrieval-RAG | E7: hyperscaler-platform | F7: n/a | J7: real-time-inference | K7: OCU-Hrs | L7: on-demand | M7: none | O7: FALSE | P7: Usage | Q7: prod | R7: customer-support | S7: governed | T7: none | U7: 1440 | V7: 345.6
A8: focus_aws_export.csv | B8: AWS | C8: Amazon Simple Storage Service | D8: storage | E8: hyperscaler-platform | F8: n/a | J8: data-prep | K8: GB-Mo | L8: on-demand | M8: none | O8: FALSE | P8: Usage | Q8: prod | R8: ml-platform | S8: governed | T8: none | U8: 4100 | V8: 94.3
A9: focus_aws_export.csv | B9: AWS | C9: Amazon Elastic Compute Cloud | D9: networking | E9: hyperscaler-platform | F9: n/a | J9: serving-idle | K9: GB | L9: on-demand | M9: none | O9: FALSE | P9: Usage | Q9: prod | R9: customer-support | S9: governed | T9: none | U9: 920 | V9: 82.8
A10: focus_aws_export.csv | B10: AWS | C10: Amazon Q | D10: licensing-subscription | E10: SaaS-embedded | F10: n/a | J10: real-time-inference | K10: seats | L10: on-demand | M10: none | O10: FALSE | P10: Purchase | Q10: prod | R10: engineering | S10: governed | T10: none | U10: 25 | V10: 475
A11: openai_usage_export.csv | B11: OpenAI | C11: OpenAI chat.completions | D11: inference | E11: managed-API | F11: direct-lab-API | G11: OpenAI | H11: mid | I11: gpt-5.4 | J11: real-time-inference | K11: per-token | L11: on-demand | M11: none | O11: FALSE | P11: Usage | Q11: prod | R11: prod-assistant | S11: governed | T11: none | U11: 12500000 | V11: 78.4
A12: openai_usage_export.csv | B12: OpenAI | C12: OpenAI chat.completions | D12: inference | E12: managed-API | F12: direct-lab-API | G12: OpenAI | H12: mid | I12: gpt-5.4-mini | J12: batch-inference | K12: per-token | L12: batch | M12: none | O12: FALSE | P12: Usage | Q12: non-prod | R12: data-enrichment | S12: governed | T12: none | U12: 30000000 | V12: 26.25
A13: openai_usage_export.csv | B13: OpenAI | C13: OpenAI embeddings | D13: inference | E13: managed-API | F13: direct-lab-API | G13: OpenAI | H13: embedding | I13: text-embedding-3-large | J13: data-prep | K13: per-token | L13: on-demand | M13: none | O13: FALSE | P13: Usage | Q13: prod | R13: prod-assistant | S13: governed | T13: none | U13: 88000000 | V13: 11.44
A14: openai_usage_export.csv | B14: OpenAI | C14: OpenAI web_search | D14: retrieval-RAG | E14: managed-API | F14: direct-lab-API | G14: OpenAI | H14: mid | I14: gpt-5.4 | J14: real-time-inference | K14: per-request | L14: on-demand | M14: none | O14: FALSE | P14: Usage | Q14: prod | R14: prod-assistant | S14: governed | T14: none | U14: 640000 | V14: 32
A15: openai_usage_export.csv | B15: OpenAI | C15: OpenAI chat.completions | D15: inference | E15: managed-API | F15: fine-tuned-hosted | G15: OpenAI | H15: mid | I15: ft:gpt-4.1:acme::r7 | J15: real-time-inference | K15: per-token | L15: on-demand | M15: none | O15: FALSE | P15: Usage | Q15: non-prod | R15: legacy-classifier | S15: governed | T15: none | U15: 5200000 | V15: 26.4
A16: anthropic_usage_export.csv | B16: Anthropic | C16: Claude API | D16: inference | E16: managed-API | F16: direct-lab-API | G16: Anthropic | H16: frontier | I16: claude-opus-4-8 | J16: real-time-inference | K16: per-token | L16: on-demand | M16: none | O16: FALSE | P16: Usage | Q16: prod | R16: support-ws | S16: governed | T16: none | U16: 2100000 | V16: 26.5
A17: anthropic_usage_export.csv | B17: Anthropic | C17: Claude API | D17: inference | E17: managed-API | F17: direct-lab-API | G17: Anthropic | H17: mid | I17: claude-sonnet-4-6 | J17: batch-inference | K17: per-token | L17: batch | M17: none | O17: FALSE | P17: Usage | Q17: prod | R17: analytics-ws | S17: governed | T17: none | U17: 9000000 | V17: 20.25
A18: anthropic_usage_export.csv | B18: Anthropic | C18: Claude API | D18: inference | E18: managed-API | F18: direct-lab-API | G18: Anthropic | H18: small-efficient | I18: claude-haiku-4-5 | J18: real-time-inference | K18: per-token | L18: on-demand | M18: none | O18: FALSE | P18: Usage | Q18: prod | R18: support-ws | S18: governed | T18: none | U18: 800000 | V18: 4.78
A19: anthropic_usage_export.csv | B19: Anthropic | C19: Claude Managed Agents | D19: orchestration-agents | E19: managed-API | F19: direct-lab-API | G19: Anthropic | J19: real-time-inference | K19: per-instance-hour | L19: on-demand | M19: none | O19: FALSE | P19: Usage | Q19: prod | R19: support-ws | S19: governed | T19: none | U19: 310 | V19: 24.8
A20: coreweave_invoice.csv | B20: CoreWeave | C20: gpu_compute | D20: compute-infra | E20: neocloud | F20: self-hosted-weights | J20: real-time-inference | K20: per-GPU-hour | L20: on-demand | M20: none | O20: FALSE | P20: Usage | Q20: non-prod | R20: ml-platform | S20: governed | T20: none | U20: 504 | V20: 17136
A21: coreweave_invoice.csv | B21: CoreWeave | C21: gpu_compute | D21: compute-infra | E21: neocloud | F21: self-hosted-weights | J21: training | K21: per-GPU-hour | L21: committed-savings-plan | M21: reserved-instance | N21: Used | O21: TRUE | P21: Usage | Q21: non-prod | R21: ml-platform | S21: governed | T21: none | U21: 720 | V21: 24192
A22: coreweave_invoice.csv | B22: CoreWeave | C22: distributed_file_storage | D22: storage | E22: neocloud | F22: n/a | J22: serving-idle | K22: per-GB-month | L22: on-demand | M22: none | O22: FALSE | P22: Usage | Q22: prod | R22: ml-platform | S22: governed | T22: none | V22: 210
A23: coreweave_invoice.csv | B23: CoreWeave | C23: network_egress | D23: networking | E23: neocloud | F23: n/a | J23: serving-idle | K23: per-GB-transfer | L23: on-demand | M23: none | O23: FALSE | P23: Usage | Q23: prod | R23: ml-platform | S23: governed | T23: none | V23: 0
A24: pinecone_invoice.csv | B24: Pinecone | C24: Pinecone Read Units | D24: retrieval-RAG | E24: SaaS-embedded | F24: n/a | J24: real-time-inference | K24: per-RU | L24: on-demand | M24: none | O24: FALSE | P24: Usage | Q24: prod | R24: rag-prod | S24: governed | T24: none | U24: 920000000 | V24: 230
A25: pinecone_invoice.csv | B25: Pinecone | C25: Pinecone Write Units | D25: retrieval-RAG | E25: SaaS-embedded | F25: n/a | J25: data-prep | K25: per-WU | L25: on-demand | M25: none | O25: FALSE | P25: Usage | Q25: prod | R25: rag-prod | S25: governed | T25: none | U25: 140000000 | V25: 56
A26: pinecone_invoice.csv | B26: Pinecone | C26: Pinecone Storage | D26: storage | E26: SaaS-embedded | F26: n/a | J26: serving-idle | K26: per-GB-month | L26: on-demand | M26: none | O26: FALSE | P26: Usage | Q26: prod | R26: rag-prod | S26: governed | T26: none | U26: 165 | V26: 54.45
A27: pinecone_invoice.csv | B27: Pinecone | C27: Pinecone Capacity Fee | D27: retrieval-RAG | E27: SaaS-embedded | F27: n/a | J27: real-time-inference | K27: per-request | L27: on-demand | M27: none | O27: FALSE | P27: Usage | Q27: prod | R27: rag-prod | S27: governed | T27: none | U27: 1 | V27: 88
A28: pinecone_invoice.csv | B28: Pinecone | C28: Pinecone Monthly Minimum True-up | D28: retrieval-RAG | E28: SaaS-embedded | F28: n/a | J28: serving-idle | K28: flat | L28: subscription | M28: none | O28: FALSE | P28: Usage | Q28: non-prod | R28: rag-dev | S28: governed | T28: none | U28: 1 | V28: 31
A29: saas_seats_invoice.csv | B29: GitHub | C29: Copilot Business | D29: licensing-subscription | E29: SaaS-embedded | F29: n/a | J29: real-time-inference | K29: per-seat | L29: subscription | M29: none | O29: FALSE | P29: Purchase | Q29: prod | R29: engineering | S29: governed | T29: none | U29: 60 | V29: 1140
A30: saas_seats_invoice.csv | B30: Acme AI | C30: Acme Agent Pro | D30: licensing-subscription | E30: SaaS-embedded | F30: n/a | J30: real-time-inference | K30: per-seat | L30: subscription | M30: none | O30: FALSE | P30: Purchase | Q30: prod | R30: unknown | S30: shadow-AI | T30: none | U30: 4 | V30: 160
